[2024-11-19T07:26:49.041+0000] {taskinstance.py:1159} INFO - Dependencies all met for dep_context=non-requeueable deps ti=<TaskInstance: etl_reddit_pipeline.s3_upload manual__2024-11-19T07:26:44.821290+00:00 [queued]>
[2024-11-19T07:26:49.049+0000] {taskinstance.py:1159} INFO - Dependencies all met for dep_context=requeueable deps ti=<TaskInstance: etl_reddit_pipeline.s3_upload manual__2024-11-19T07:26:44.821290+00:00 [queued]>
[2024-11-19T07:26:49.050+0000] {taskinstance.py:1361} INFO - Starting attempt 1 of 1
[2024-11-19T07:26:49.060+0000] {taskinstance.py:1382} INFO - Executing <Task(PythonOperator): s3_upload> on 2024-11-19 07:26:44.821290+00:00
[2024-11-19T07:26:49.064+0000] {standard_task_runner.py:57} INFO - Started process 71 to run task
[2024-11-19T07:26:49.068+0000] {standard_task_runner.py:84} INFO - Running: ['airflow', 'tasks', 'run', 'etl_reddit_pipeline', 's3_upload', 'manual__2024-11-19T07:26:44.821290+00:00', '--job-id', '26', '--raw', '--subdir', 'DAGS_FOLDER/reddit_dag.py', '--cfg-path', '/tmp/tmpiwnvf82j']
[2024-11-19T07:26:49.071+0000] {standard_task_runner.py:85} INFO - Job 26: Subtask s3_upload
[2024-11-19T07:26:49.239+0000] {task_command.py:416} INFO - Running <TaskInstance: etl_reddit_pipeline.s3_upload manual__2024-11-19T07:26:44.821290+00:00 [running]> on host 9f42dd3b4e06
[2024-11-19T07:26:49.329+0000] {taskinstance.py:1662} INFO - Exporting env vars: AIRFLOW_CTX_DAG_OWNER='Bao Nguyen' AIRFLOW_CTX_DAG_ID='etl_reddit_pipeline' AIRFLOW_CTX_TASK_ID='s3_upload' AIRFLOW_CTX_EXECUTION_DATE='2024-11-19T07:26:44.821290+00:00' AIRFLOW_CTX_TRY_NUMBER='1' AIRFLOW_CTX_DAG_RUN_ID='manual__2024-11-19T07:26:44.821290+00:00'
[2024-11-19T07:26:50.263+0000] {logging_mixin.py:151} INFO - Bucket already exists
[2024-11-19T07:26:50.558+0000] {taskinstance.py:1937} ERROR - Task failed with exception
Traceback (most recent call last):
  File "/home/airflow/.local/lib/python3.9/site-packages/s3fs/core.py", line 706, in _lsdir
    async for c in self._iterdir(
  File "/home/airflow/.local/lib/python3.9/site-packages/s3fs/core.py", line 756, in _iterdir
    async for i in it:
  File "/home/airflow/.local/lib/python3.9/site-packages/aiobotocore/paginate.py", line 30, in __anext__
    response = await self._make_request(current_kwargs)
  File "/home/airflow/.local/lib/python3.9/site-packages/aiobotocore/client.py", line 383, in _make_api_call
    raise error_class(parsed_response, operation_name)
botocore.exceptions.ClientError: An error occurred (AccessDenied) when calling the ListObjectsV2 operation: Access Denied

The above exception was the direct cause of the following exception:

Traceback (most recent call last):
  File "/home/airflow/.local/lib/python3.9/site-packages/airflow/operators/python.py", line 192, in execute
    return_value = self.execute_callable()
  File "/home/airflow/.local/lib/python3.9/site-packages/airflow/operators/python.py", line 209, in execute_callable
    return self.python_callable(*self.op_args, **self.op_kwargs)
  File "/opt/airflow/pipelines/aws_s3_pipeline.py", line 9, in upload_s3_pipeline
    upload_to_s3(s3, file_path, AWS_BUCKET_NAME, file_path.split('/')[-1])
  File "/opt/airflow/etls/aws_etl.py", line 25, in upload_to_s3
    s3.put(file_path, bucket+'/raw/'+s3_file_name)
  File "/home/airflow/.local/lib/python3.9/site-packages/fsspec/asyn.py", line 118, in wrapper
    return sync(self.loop, func, *args, **kwargs)
  File "/home/airflow/.local/lib/python3.9/site-packages/fsspec/asyn.py", line 103, in sync
    raise return_result
  File "/home/airflow/.local/lib/python3.9/site-packages/fsspec/asyn.py", line 56, in _runner
    result[0] = await coro
  File "/home/airflow/.local/lib/python3.9/site-packages/fsspec/asyn.py", line 536, in _put
    trailing_sep(rpath) or await self._isdir(rpath)
  File "/home/airflow/.local/lib/python3.9/site-packages/s3fs/core.py", line 1411, in _isdir
    return bool(await self._lsdir(path))
  File "/home/airflow/.local/lib/python3.9/site-packages/s3fs/core.py", line 719, in _lsdir
    raise translate_boto_error(e)
PermissionError: Access Denied
[2024-11-19T07:26:50.571+0000] {taskinstance.py:1400} INFO - Marking task as FAILED. dag_id=etl_reddit_pipeline, task_id=s3_upload, execution_date=20241119T072644, start_date=20241119T072649, end_date=20241119T072650
[2024-11-19T07:26:50.584+0000] {standard_task_runner.py:104} ERROR - Failed to execute job 26 for task s3_upload (Access Denied; 71)
[2024-11-19T07:26:50.608+0000] {local_task_job_runner.py:228} INFO - Task exited with return code 1
[2024-11-19T07:26:50.728+0000] {taskinstance.py:2778} INFO - 0 downstream tasks scheduled from follow-on schedule check
